<?xml version="1.0" encoding="utf-8"?>
<!-- =================================================================================== -->
<!-- |    This document was autogenerated by xacro from drone.xml                      | -->
<!-- |    EDITING THIS FILE BY HAND IS NOT RECOMMENDED                                 | -->
<!-- =================================================================================== -->
<robot name="drone">
  <material name="white">
    <color rgba="0.8 0.8 0.8 1"/>
  </material>
  <material name="black">
    <color rgba="0.1 0.1 0.1 1"/>
  </material>
  <material name="red">
    <color rgba="0.8 0.01 0.01 1"/>
  </material>
  <material name="blue">
    <color rgba="0.01 0.01 0.8 1"/>
  </material>
  <material name="golden">
    <color rgba="0.83137254902 0.686274509804 0.21568627451 1"/>
  </material>
  <!-- <xacro:property name="govde_m" value="5" /> -->
  <link name="govde">
    <visual>
      <origin rpy="0 0 -3.14159263" xyz="0 0 0"/>
      <geometry>
        <!-- <box size="${uzunluk/2} ${uzunluk/2} ${radius}" /> -->
        <cylinder length="0.01" radius="0.1125"/>
      </geometry>
      <material name="white"/>
    </visual>
    <collision>
      <origin rpy="0 0 -3.14159263" xyz="0 0 0"/>
      <geometry>
        <!-- <box size="${uzunluk/2} ${uzunluk/2} ${radius}" /> -->
        <cylinder length="0.01" radius="0.1125"/>
      </geometry>
    </collision>
    <inertial>
      <origin rpy="0 0 0.0" xyz="0 0 0"/>
      <mass value="0.5"/>
      <inertia ixx="0.0139958705275" ixy="0" ixz="0" iyy="0.0139958705275" iyz="0" izz="0.00239894389428"/>
    </inertial>
  </link>
  <link name="imu">
    <visual>
      <geometry>
        <box size="0.02 0.02 0.005"/>
      </geometry>
    </visual>
    <collision>
      <geometry>
        <box size="0.02 0.02 0.005"/>
      </geometry>
    </collision>
    <inertial>
      <mass value="1e-5"/>
      <origin rpy="0 0 0" xyz="0 0 0"/>
      <inertia ixx="1e-6" ixy="0" ixz="0" iyy="1e-6" iyz="0" izz="1e-6"/>
    </inertial>
  </link>
  <joint name="imu_eklemi" type="fixed">
    <parent link="govde"/>
    <child link="imu"/>
    <origin rpy="0 0 0" xyz="0 0 0.005"/>
  </joint>
  <link name="on_kol">
    <visual>
      <origin rpy="1.570796315 0  1.570796315 " xyz="0 0 0"/>
      <geometry>
        <cylinder length="0.15" radius="0.008"/>
      </geometry>
      <material name="red"/>
    </visual>
    <collision>
      <origin rpy="1.570796315 0 1.570796315 " xyz="0 0 0"/>
      <geometry>
        <cylinder length="0.15" radius="0.008"/>
      </geometry>
    </collision>
    <inertial>
      <origin rpy="0 0 0.7853981575" xyz="0 0 0"/>
      <mass value="0.055"/>
      <inertia ixx="0.0139958705275" ixy="0" ixz="0" iyy="0.0139958705275" iyz="0" izz="0.00239894389428"/>
    </inertial>
  </link>
  <joint name="on_kol_eklemi" type="fixed">
    <parent link="govde"/>
    <child link="on_kol"/>
    <origin rpy="0 0 0" xyz="0.15 0.0 0"/>
  </joint>
  <link name="on_motor">
    <visual>
      <origin rpy="0 0 0" xyz="0 0 0"/>
      <geometry>
        <cylinder length="0.04" radius="0.015"/>
      </geometry>
      <material name="blue"/>
    </visual>
    <collision>
      <origin rpy="0 0 0" xyz="0 0 0"/>
      <geometry>
        <cylinder length="0.04" radius="0.015"/>
      </geometry>
    </collision>
    <inertial>
      <origin rpy="0 0 0" xyz="0 0 0"/>
      <mass value="0.01"/>
      <inertia ixx="5.02156910087e-06" ixy="0" ixz="0" iyy="5.02156910087e-06" iyz="0" izz="4.78651980402e-07"/>
    </inertial>
  </link>
  <joint name="on_kol_motor_eklemi" type="fixed">
    <parent link="on_kol"/>
    <child link="on_motor"/>
    <origin rpy="0 0 0" xyz="0.0625 0.0 0.02"/>
  </joint>
  <link name="on_motor_mili">
    <visual>
      <origin rpy="0 0  1.570796315 " xyz="0 0 0"/>
      <geometry>
        <cylinder length="0.035" radius="0.004"/>
      </geometry>
      <material name="black"/>
    </visual>
    <collision>
      <origin rpy="0 0 1.570796315 " xyz="0 0 0"/>
      <geometry>
        <cylinder length="0.035" radius="0.004"/>
      </geometry>
    </collision>
    <inertial>
      <origin rpy="0 0 0" xyz="0 0 0"/>
      <mass value="0.01"/>
      <inertia ixx="5.61069173282e-07" ixy="0" ixz="0" iyy="5.61069173282e-07" iyz="0" izz="1.99438325167e-08"/>
    </inertial>
  </link>
  <joint name="on_motor_mili_eklemi" type="fixed">
    <parent link="on_motor"/>
    <child link="on_motor_mili"/>
    <origin rpy="0 0 0" xyz="0 0 0.0175"/>
  </joint>
  <link name="on_pervane">
    <visual>
      <origin rpy="0 0 0" xyz="0 0 0"/>
      <geometry>
        <box size="0.0110066666667 0.2 0.005"/>
      </geometry>
      <material name="golden"/>
    </visual>
    <collision>
      <origin rpy="0 0 0" xyz="0 0 0"/>
      <geometry>
        <box size="0.0110066666667 0.2 0.005"/>
      </geometry>
    </collision>
    <inertial>
      <origin rpy="0 0 0" xyz="0 0 0"/>
      <mass value="0.055"/>
      <inertia ixx="0" ixy="0" ixz="0" iyy="0" iyz="0" izz="4.83534230602e-07"/>
    </inertial>
  </link>
  <joint name="on_pervane_eklemi" type="continuous">
    <parent link="on_motor_mili"/>
    <child link="on_pervane"/>
    <origin rpy="0 0 0" xyz="0 0 0.02"/>
    <axis rpy="0 0 0" xyz="0 0 1"/>
  </joint>
  <transmission name="on_pervane_eklemi">
    <type>transmission_interface/SimpleTransmission</type>
    <joint name="on_pervane_eklemi">
      <hardwareInterface>hardware_interface/VelocityJointInterface</hardwareInterface>
    </joint>
    <actuator name="on_pervane_BLDC">
      <hardwareInterface>hardware_interface/VelocityJointInterface</hardwareInterface>
      <mechanicalReduction>1</mechanicalReduction>
    </actuator>
  </transmission>
  <gazebo reference="on_motor">
    <material>Gazebo/Blue</material>
  </gazebo>
  <gazebo reference="on_motor_mili">
    <material>Gazebo/White</material>
  </gazebo>
  <gazebo reference="on_pervane">
    <material>Gazebo/Gold</material>
  </gazebo>
  <gazebo reference="on_kol">
    <material>Gazebo/Red</material>
  </gazebo>
  <link name="sag_kol">
    <visual>
      <origin rpy="1.570796315 0  3.14159263 " xyz="0 0 0"/>
      <geometry>
        <cylinder length="0.15" radius="0.008"/>
      </geometry>
      <material name="red"/>
    </visual>
    <collision>
      <origin rpy="1.570796315 0 3.14159263 " xyz="0 0 0"/>
      <geometry>
        <cylinder length="0.15" radius="0.008"/>
      </geometry>
    </collision>
    <inertial>
      <origin rpy="0 0 0.7853981575" xyz="0 0 0"/>
      <mass value="0.055"/>
      <inertia ixx="0.0139958705275" ixy="0" ixz="0" iyy="0.0139958705275" iyz="0" izz="0.00239894389428"/>
    </inertial>
  </link>
  <joint name="sag_kol_eklemi" type="fixed">
    <parent link="govde"/>
    <child link="sag_kol"/>
    <origin rpy="0 0 0" xyz="0.0 -0.15 0"/>
  </joint>
  <link name="sag_motor">
    <visual>
      <origin rpy="0 0 0" xyz="0 0 0"/>
      <geometry>
        <cylinder length="0.04" radius="0.015"/>
      </geometry>
      <material name="blue"/>
    </visual>
    <collision>
      <origin rpy="0 0 0" xyz="0 0 0"/>
      <geometry>
        <cylinder length="0.04" radius="0.015"/>
      </geometry>
    </collision>
    <inertial>
      <origin rpy="0 0 0" xyz="0 0 0"/>
      <mass value="0.01"/>
      <inertia ixx="5.02156910087e-06" ixy="0" ixz="0" iyy="5.02156910087e-06" iyz="0" izz="4.78651980402e-07"/>
    </inertial>
  </link>
  <joint name="sag_kol_motor_eklemi" type="fixed">
    <parent link="sag_kol"/>
    <child link="sag_motor"/>
    <origin rpy="0 0 0" xyz="0.0 -0.0625 0.02"/>
  </joint>
  <link name="sag_motor_mili">
    <visual>
      <origin rpy="0 0  3.14159263 " xyz="0 0 0"/>
      <geometry>
        <cylinder length="0.035" radius="0.004"/>
      </geometry>
      <material name="black"/>
    </visual>
    <collision>
      <origin rpy="0 0 3.14159263 " xyz="0 0 0"/>
      <geometry>
        <cylinder length="0.035" radius="0.004"/>
      </geometry>
    </collision>
    <inertial>
      <origin rpy="0 0 0" xyz="0 0 0"/>
      <mass value="0.01"/>
      <inertia ixx="5.61069173282e-07" ixy="0" ixz="0" iyy="5.61069173282e-07" iyz="0" izz="1.99438325167e-08"/>
    </inertial>
  </link>
  <joint name="sag_motor_mili_eklemi" type="fixed">
    <parent link="sag_motor"/>
    <child link="sag_motor_mili"/>
    <origin rpy="0 0 0" xyz="0 0 0.0175"/>
  </joint>
  <link name="sag_pervane">
    <visual>
      <origin rpy="0 0 0" xyz="0 0 0"/>
      <geometry>
        <box size="0.0110066666667 0.2 0.005"/>
      </geometry>
      <material name="golden"/>
    </visual>
    <collision>
      <origin rpy="0 0 0" xyz="0 0 0"/>
      <geometry>
        <box size="0.0110066666667 0.2 0.005"/>
      </geometry>
    </collision>
    <inertial>
      <origin rpy="0 0 0" xyz="0 0 0"/>
      <mass value="0.055"/>
      <inertia ixx="0" ixy="0" ixz="0" iyy="0" iyz="0" izz="4.83534230602e-07"/>
    </inertial>
  </link>
  <joint name="sag_pervane_eklemi" type="continuous">
    <parent link="sag_motor_mili"/>
    <child link="sag_pervane"/>
    <origin rpy="0 0 0" xyz="0 0 0.02"/>
    <axis rpy="0 0 0" xyz="0 0 1"/>
  </joint>
  <transmission name="sag_pervane_eklemi">
    <type>transmission_interface/SimpleTransmission</type>
    <joint name="sag_pervane_eklemi">
      <hardwareInterface>hardware_interface/VelocityJointInterface</hardwareInterface>
    </joint>
    <actuator name="sag_pervane_BLDC">
      <hardwareInterface>hardware_interface/VelocityJointInterface</hardwareInterface>
      <mechanicalReduction>1</mechanicalReduction>
    </actuator>
  </transmission>
  <gazebo reference="sag_motor">
    <material>Gazebo/Blue</material>
  </gazebo>
  <gazebo reference="sag_motor_mili">
    <material>Gazebo/White</material>
  </gazebo>
  <gazebo reference="sag_pervane">
    <material>Gazebo/Gold</material>
  </gazebo>
  <gazebo reference="sag_kol">
    <material>Gazebo/Red</material>
  </gazebo>
  <link name="arka_kol">
    <visual>
      <origin rpy="1.570796315 0  1.570796315 " xyz="0 0 0"/>
      <geometry>
        <cylinder length="0.15" radius="0.008"/>
      </geometry>
      <material name="red"/>
    </visual>
    <collision>
      <origin rpy="1.570796315 0 1.570796315 " xyz="0 0 0"/>
      <geometry>
        <cylinder length="0.15" radius="0.008"/>
      </geometry>
    </collision>
    <inertial>
      <origin rpy="0 0 0.7853981575" xyz="0 0 0"/>
      <mass value="0.055"/>
      <inertia ixx="0.0139958705275" ixy="0" ixz="0" iyy="0.0139958705275" iyz="0" izz="0.00239894389428"/>
    </inertial>
  </link>
  <joint name="arka_kol_eklemi" type="fixed">
    <parent link="govde"/>
    <child link="arka_kol"/>
    <origin rpy="0 0 0" xyz="-0.15 0.0 0"/>
  </joint>
  <link name="arka_motor">
    <visual>
      <origin rpy="0 0 0" xyz="0 0 0"/>
      <geometry>
        <cylinder length="0.04" radius="0.015"/>
      </geometry>
      <material name="blue"/>
    </visual>
    <collision>
      <origin rpy="0 0 0" xyz="0 0 0"/>
      <geometry>
        <cylinder length="0.04" radius="0.015"/>
      </geometry>
    </collision>
    <inertial>
      <origin rpy="0 0 0" xyz="0 0 0"/>
      <mass value="0.01"/>
      <inertia ixx="5.02156910087e-06" ixy="0" ixz="0" iyy="5.02156910087e-06" iyz="0" izz="4.78651980402e-07"/>
    </inertial>
  </link>
  <joint name="arka_kol_motor_eklemi" type="fixed">
    <parent link="arka_kol"/>
    <child link="arka_motor"/>
    <origin rpy="0 0 0" xyz="-0.0625 0.0 0.02"/>
  </joint>
  <link name="arka_motor_mili">
    <visual>
      <origin rpy="0 0  1.570796315 " xyz="0 0 0"/>
      <geometry>
        <cylinder length="0.035" radius="0.004"/>
      </geometry>
      <material name="black"/>
    </visual>
    <collision>
      <origin rpy="0 0 1.570796315 " xyz="0 0 0"/>
      <geometry>
        <cylinder length="0.035" radius="0.004"/>
      </geometry>
    </collision>
    <inertial>
      <origin rpy="0 0 0" xyz="0 0 0"/>
      <mass value="0.01"/>
      <inertia ixx="5.61069173282e-07" ixy="0" ixz="0" iyy="5.61069173282e-07" iyz="0" izz="1.99438325167e-08"/>
    </inertial>
  </link>
  <joint name="arka_motor_mili_eklemi" type="fixed">
    <parent link="arka_motor"/>
    <child link="arka_motor_mili"/>
    <origin rpy="0 0 0" xyz="0 0 0.0175"/>
  </joint>
  <link name="arka_pervane">
    <visual>
      <origin rpy="0 0 0" xyz="0 0 0"/>
      <geometry>
        <box size="0.0110066666667 0.2 0.005"/>
      </geometry>
      <material name="golden"/>
    </visual>
    <collision>
      <origin rpy="0 0 0" xyz="0 0 0"/>
      <geometry>
        <box size="0.0110066666667 0.2 0.005"/>
      </geometry>
    </collision>
    <inertial>
      <origin rpy="0 0 0" xyz="0 0 0"/>
      <mass value="0.055"/>
      <inertia ixx="0" ixy="0" ixz="0" iyy="0" iyz="0" izz="4.83534230602e-07"/>
    </inertial>
  </link>
  <joint name="arka_pervane_eklemi" type="continuous">
    <parent link="arka_motor_mili"/>
    <child link="arka_pervane"/>
    <origin rpy="0 0 0" xyz="0 0 0.02"/>
    <axis rpy="0 0 0" xyz="0 0 1"/>
  </joint>
  <transmission name="arka_pervane_eklemi">
    <type>transmission_interface/SimpleTransmission</type>
    <joint name="arka_pervane_eklemi">
      <hardwareInterface>hardware_interface/VelocityJointInterface</hardwareInterface>
    </joint>
    <actuator name="arka_pervane_BLDC">
      <hardwareInterface>hardware_interface/VelocityJointInterface</hardwareInterface>
      <mechanicalReduction>1</mechanicalReduction>
    </actuator>
  </transmission>
  <gazebo reference="arka_motor">
    <material>Gazebo/Blue</material>
  </gazebo>
  <gazebo reference="arka_motor_mili">
    <material>Gazebo/White</material>
  </gazebo>
  <gazebo reference="arka_pervane">
    <material>Gazebo/Gold</material>
  </gazebo>
  <gazebo reference="arka_kol">
    <material>Gazebo/Red</material>
  </gazebo>
  <link name="sol_kol">
    <visual>
      <origin rpy="1.570796315 0  3.14159263 " xyz="0 0 0"/>
      <geometry>
        <cylinder length="0.15" radius="0.008"/>
      </geometry>
      <material name="red"/>
    </visual>
    <collision>
      <origin rpy="1.570796315 0 3.14159263 " xyz="0 0 0"/>
      <geometry>
        <cylinder length="0.15" radius="0.008"/>
      </geometry>
    </collision>
    <inertial>
      <origin rpy="0 0 0.7853981575" xyz="0 0 0"/>
      <mass value="0.055"/>
      <inertia ixx="0.0139958705275" ixy="0" ixz="0" iyy="0.0139958705275" iyz="0" izz="0.00239894389428"/>
    </inertial>
  </link>
  <joint name="sol_kol_eklemi" type="fixed">
    <parent link="govde"/>
    <child link="sol_kol"/>
    <origin rpy="0 0 0" xyz="0.0 0.15 0"/>
  </joint>
  <link name="sol_motor">
    <visual>
      <origin rpy="0 0 0" xyz="0 0 0"/>
      <geometry>
        <cylinder length="0.04" radius="0.015"/>
      </geometry>
      <material name="blue"/>
    </visual>
    <collision>
      <origin rpy="0 0 0" xyz="0 0 0"/>
      <geometry>
        <cylinder length="0.04" radius="0.015"/>
      </geometry>
    </collision>
    <inertial>
      <origin rpy="0 0 0" xyz="0 0 0"/>
      <mass value="0.01"/>
      <inertia ixx="5.02156910087e-06" ixy="0" ixz="0" iyy="5.02156910087e-06" iyz="0" izz="4.78651980402e-07"/>
    </inertial>
  </link>
  <joint name="sol_kol_motor_eklemi" type="fixed">
    <parent link="sol_kol"/>
    <child link="sol_motor"/>
    <origin rpy="0 0 0" xyz="0.0 0.0625 0.02"/>
  </joint>
  <link name="sol_motor_mili">
    <visual>
      <origin rpy="0 0  3.14159263 " xyz="0 0 0"/>
      <geometry>
        <cylinder length="0.035" radius="0.004"/>
      </geometry>
      <material name="black"/>
    </visual>
    <collision>
      <origin rpy="0 0 3.14159263 " xyz="0 0 0"/>
      <geometry>
        <cylinder length="0.035" radius="0.004"/>
      </geometry>
    </collision>
    <inertial>
      <origin rpy="0 0 0" xyz="0 0 0"/>
      <mass value="0.01"/>
      <inertia ixx="5.61069173282e-07" ixy="0" ixz="0" iyy="5.61069173282e-07" iyz="0" izz="1.99438325167e-08"/>
    </inertial>
  </link>
  <joint name="sol_motor_mili_eklemi" type="fixed">
    <parent link="sol_motor"/>
    <child link="sol_motor_mili"/>
    <origin rpy="0 0 0" xyz="0 0 0.0175"/>
  </joint>
  <link name="sol_pervane">
    <visual>
      <origin rpy="0 0 0" xyz="0 0 0"/>
      <geometry>
        <box size="0.0110066666667 0.2 0.005"/>
      </geometry>
      <material name="golden"/>
    </visual>
    <collision>
      <origin rpy="0 0 0" xyz="0 0 0"/>
      <geometry>
        <box size="0.0110066666667 0.2 0.005"/>
      </geometry>
    </collision>
    <inertial>
      <origin rpy="0 0 0" xyz="0 0 0"/>
      <mass value="0.055"/>
      <inertia ixx="0" ixy="0" ixz="0" iyy="0" iyz="0" izz="4.83534230602e-07"/>
    </inertial>
  </link>
  <joint name="sol_pervane_eklemi" type="continuous">
    <parent link="sol_motor_mili"/>
    <child link="sol_pervane"/>
    <origin rpy="0 0 0" xyz="0 0 0.02"/>
    <axis rpy="0 0 0" xyz="0 0 1"/>
  </joint>
  <transmission name="sol_pervane_eklemi">
    <type>transmission_interface/SimpleTransmission</type>
    <joint name="sol_pervane_eklemi">
      <hardwareInterface>hardware_interface/VelocityJointInterface</hardwareInterface>
    </joint>
    <actuator name="sol_pervane_BLDC">
      <hardwareInterface>hardware_interface/VelocityJointInterface</hardwareInterface>
      <mechanicalReduction>1</mechanicalReduction>
    </actuator>
  </transmission>
  <gazebo reference="sol_motor">
    <material>Gazebo/Blue</material>
  </gazebo>
  <gazebo reference="sol_motor_mili">
    <material>Gazebo/White</material>
  </gazebo>
  <gazebo reference="sol_pervane">
    <material>Gazebo/Gold</material>
  </gazebo>
  <gazebo reference="sol_kol">
    <material>Gazebo/Red</material>
  </gazebo>
  <gazebo>
    <!-- Provide a Positive Velocity -->
    <plugin filename="libLiftDragPlugin.so" name="on_pervane">
      <a0>0.1</a0>
      <cla>0.1</cla>
      <cda>0.01</cda>
      <cma>0.0</cma>
      <alpha_stall>0.2</alpha_stall>
      <cla_stall>-0.2</cla_stall>
      <cda_stall>1.0</cda_stall>
      <cma_stall>0.0</cma_stall>
      <cp>0 0.5 0</cp>
      <area>0.762</area>
      <air_density>1.2041</air_density>
      <forward>1 0 0</forward>
      <upward>0 0 -1</upward>
      <link_name>on_pervane</link_name>
      <control_joint>on_pervane_eklemi</control_joint>
    </plugin>
  </gazebo>
  <gazebo>
    <!-- Provide a Positive Velocity -->
    <plugin filename="libLiftDragPlugin.so" name="sol_pervane">
      <a0>0.1</a0>
      <cla>0.1</cla>
      <cda>0.01</cda>
      <cma>0.0</cma>
      <alpha_stall>0.2</alpha_stall>
      <cla_stall>-0.2</cla_stall>
      <cda_stall>1.0</cda_stall>
      <cma_stall>0.0</cma_stall>
      <cp>0 0.5 0</cp>
      <area>0.762</area>
      <air_density>1.2041</air_density>
      <forward>1 0 0</forward>
      <upward>0 0 1</upward>
      <link_name>sol_pervane</link_name>
      <control_joint>sol_pervane_eklemi</control_joint>
    </plugin>
  </gazebo>
  <gazebo>
    <!-- Provide a Positive Velocity -->
    <plugin filename="libLiftDragPlugin.so" name="sag_pervane">
      <a0>0.1</a0>
      <cla>0.1</cla>
      <cda>0.01</cda>
      <cma>0.0</cma>
      <alpha_stall>0.2</alpha_stall>
      <cla_stall>-0.2</cla_stall>
      <cda_stall>1.0</cda_stall>
      <cma_stall>0.0</cma_stall>
      <cp>0 0.5 0</cp>
      <area>0.762</area>
      <air_density>1.2041</air_density>
      <forward>1 0 0</forward>
      <upward>0 0 1</upward>
      <link_name>sag_pervane</link_name>
      <control_joint>sag_pervane_eklemi</control_joint>
    </plugin>
  </gazebo>
  <gazebo>
    <!-- Provide a Positive Velocity -->
    <plugin filename="libLiftDragPlugin.so" name="arka_pervane">
      <a0>0.1</a0>
      <cla>0.1</cla>
      <cda>0.01</cda>
      <cma>0.0</cma>
      <alpha_stall>0.2</alpha_stall>
      <cla_stall>-0.2</cla_stall>
      <cda_stall>1.0</cda_stall>
      <cma_stall>0.0</cma_stall>
      <cp>0 0.5 0</cp>
      <area>0.762</area>
      <air_density>1.2041</air_density>
      <forward>1 0 0</forward>
      <upward>0 0 -1</upward>
      <link_name>arka_pervane</link_name>
      <control_joint>arka_pervane_eklemi</control_joint>
    </plugin>
  </gazebo>
  <gazebo reference="imu">
    <gravity>true</gravity>
    <sensor name="imu_sensor" type="imu">
      <always_on>true</always_on>
      <update_rate>100</update_rate>
      <visualize>true</visualize>
      <topic>__default_topic__</topic>
      <plugin filename="libgazebo_ros_imu_sensor.so" name="imu_plugin">
        <topicName>imu</topicName>
        <bodyName>imu</bodyName>
        <updateRateHZ>10.0</updateRateHZ>
        <gaussianNoise>0.0</gaussianNoise>
        <xyzOffset>0 0 0</xyzOffset>
        <rpyOffset>0 0 0</rpyOffset>
        <frameName>imu</frameName>
      </plugin>
      <pose>0 0 0 0 0 0</pose>
    </sensor>
  </gazebo>
  <gazebo reference="imu">
    <material>Gazebo/Red</material>
  </gazebo>
  <gazebo>
    <plugin filename="libgazebo_ros_control.so" name="gazebo_ros_control">
      <robotNameSpace>/drone</robotNameSpace>
      <robotSimType>gazebo_ros_control/DefaultRobotHWSim</robotSimType>
      <legacyModeNS>true</legacyModeNS>
    </plugin>
  </gazebo>
</robot>

