<?xml version="1.0" encoding="utf-8"?>
<robot name="robot_kolu">
  <link name="base_link">
    <visual>
      <geometry>
        <cylinder length="0.01" radius="0.2"/>
      </geometry>
      <origin rpy="0 0 0" xyz="0 0 0"/>
      <material name="yellow">
        <color rgba="1 1 0 1"/>
      </material>
    </visual>
    <collision>
      <geometry>
        <cylinder length="0.03" radius="0.2"/>
      </geometry>
      <origin rpy="0 0 0" xyz="0 0 0"/>
    </collision>
    <inertial>
      <mass value="1"/>
      <inertia ixx="0.5" ixy="0.0" ixz="0.0" iyy="0.5" iyz="0.0" izz="0.5"/>
    </inertial>
  </link>
  <joint name="govde_eklemi" type="revolute">
    <parent link="base_link"/>
    <child link="govde_uzvu"/>
    <origin xyz="0 0 0.1"/>
    <axis xyz="0 0 1"/>
    <limit effort="300" lower="-3.14" upper="3.14" velocity="0.1"/>
    <dynamics damping="50" friction="1"/>
  </joint>
  <link name="govde_uzvu">
    <visual>
      <geometry>
        <cylinder length="0.4" radius="0.04"/>
      </geometry>
      <origin rpy="0 0 0" xyz="0 0 0.09"/>
      <material name="red">
        <color rgba="0 0 1 1"/>
      </material>
    </visual>
    <collision>
      <geometry>
        <cylinder length="0.4" radius="0.06"/>
      </geometry>
      <origin rpy="0 0 0" xyz="0 0 0.09"/>
    </collision>
    <inertial>
      <mass value="1"/>
      <inertia ixx="0.5" ixy="0.0" ixz="0.0" iyy="0.5" iyz="0.0" izz="0.5"/>
    </inertial>
  </link>
  <joint name="kol_eklemi" type="revolute">
    <parent link="govde_uzvu"/>
    <child link="kol_uzvu"/>
    <origin xyz="0 0 0.2"/>
    <axis xyz="0 1 0"/>
    <limit effort="300" lower="-4.64" upper="-1.5" velocity="0.1"/>
    <dynamics damping="50" friction="1"/>
  </joint>
  <link name="kol_uzvu">
    <visual>
      <geometry>
        <cylinder length="0.4" radius="0.04"/>
      </geometry>
      <origin rpy="0 1.5 0" xyz="0 0 0"/>
      <material name="green">
        <color rgba="1 0 0 1"/>
      </material>
    </visual>
    <collision>
      <geometry>
        <cylinder length="0.4" radius="0.24"/>
      </geometry>
      <origin rpy="0 1.5 0" xyz="0 0 0"/>
    </collision>
    <inertial>
      <mass value="1"/>
      <inertia ixx="0.5" ixy="0.0" ixz="0.0" iyy="0.5" iyz="0.0" izz="0.5"/>
    </inertial>
  </link>
</robot>
